Traceback (most recent call last):
  File "/home/brad/miniconda3/envs/pycourse/lib/python3.8/site-packages/jupyter_cache/executors/utils.py", line 51, in single_nb_execution
    executenb(
  File "/home/brad/miniconda3/envs/pycourse/lib/python3.8/site-packages/nbclient/client.py", line 1077, in execute
    return NotebookClient(nb=nb, resources=resources, km=km, **kwargs).execute()
  File "/home/brad/miniconda3/envs/pycourse/lib/python3.8/site-packages/nbclient/util.py", line 74, in wrapped
    return just_run(coro(*args, **kwargs))
  File "/home/brad/miniconda3/envs/pycourse/lib/python3.8/site-packages/nbclient/util.py", line 53, in just_run
    return loop.run_until_complete(coro)
  File "/home/brad/miniconda3/envs/pycourse/lib/python3.8/asyncio/base_events.py", line 616, in run_until_complete
    return future.result()
  File "/home/brad/miniconda3/envs/pycourse/lib/python3.8/site-packages/nbclient/client.py", line 526, in async_execute
    await self.async_execute_cell(
  File "/home/brad/miniconda3/envs/pycourse/lib/python3.8/site-packages/nbclient/client.py", line 822, in async_execute_cell
    self._check_raise_for_error(cell, exec_reply)
  File "/home/brad/miniconda3/envs/pycourse/lib/python3.8/site-packages/nbclient/client.py", line 730, in _check_raise_for_error
    raise CellExecutionError.from_cell_and_msg(cell, exec_reply['content'])
nbclient.exceptions.CellExecutionError: An error occurred while executing the following cell:
------------------
class MyDF():
    def __init__(self, **kwargs):
        self.is_df = True
        
df2 = MyDF(a=1, b=np.ones(3))
df2.is_df
------------------

[0;31m---------------------------------------------------------------------------[0m
[0;31mNameError[0m                                 Traceback (most recent call last)
[0;32m<ipython-input-12-ca27e129039d>[0m in [0;36m<module>[0;34m[0m
[1;32m      3[0m         [0mself[0m[0;34m.[0m[0mis_df[0m [0;34m=[0m [0;32mTrue[0m[0;34m[0m[0;34m[0m[0m
[1;32m      4[0m [0;34m[0m[0m
[0;32m----> 5[0;31m [0mdf2[0m [0;34m=[0m [0mMyDF[0m[0;34m([0m[0ma[0m[0;34m=[0m[0;36m1[0m[0;34m,[0m [0mb[0m[0;34m=[0m[0mnp[0m[0;34m.[0m[0mones[0m[0;34m([0m[0;36m3[0m[0;34m)[0m[0;34m)[0m[0;34m[0m[0;34m[0m[0m
[0m[1;32m      6[0m [0mdf2[0m[0;34m.[0m[0mis_df[0m[0;34m[0m[0;34m[0m[0m

[0;31mNameError[0m: name 'np' is not defined
NameError: name 'np' is not defined

